Workbook

Sheet Parametri
B2: PARAMETRI DEL SISTEMA DI SCORING
B4: PESI KPI (modificabili)
B5: KPI | C5: Peso % | D5: Note
B6: Produttività | C6: 0.4 | D6: Indicatore prioritario — può essere negativo
B7: IUQ | C7: 0.3 | D7: Qualità SLA — scala assoluta
B8: LDS | C8: 0.2 | D8: Livello di Servizio — scostamento vs SLA
B9: TMG | C9: 0.1 | D9: Tempo Medio Gestione — scala invertita
B10: TOTALE | C10: =SUM(C6:C9) -> 1 | D10: ⚠️ Deve essere = 100%
B12: FASCE PRODUTTIVITÀ — Scostamento % vs target (punteggio con segno)
B13: Scostamento % (Da) | C13: Scostamento % (A) | D13: Punteggio
B14: ≥ +8% | D14: 10
B15: 0.06 | C15: 0.0799 | D15: 8
B16: 0.04 | C16: 0.0599 | D16: 6
B17: 0.02 | C17: 0.0399 | D17: 4
B18: 0 | C18: 0.0199 | D18: 2
B19: -0.019 | C19: -0.001 | D19: -2
B20: -0.039 | C20: -0.02 | D20: -5
B21: ≤ -4% | C21: -0.04 | D21: -10
B23: FASCE IUQ — % SLA in target (scala assoluta)
B24: % SLA in target (Da) | C24: % SLA in target (A) | D24: Punteggio
B25: ≥ 95% | C25: < 70% | D25: 10
B26: 0.9 | C26: 0.9499 | D26: 8
B27: 0.85 | C27: 0.8999 | D27: 6
B28: 0.8 | C28: 0.8499 | D28: 4
B29: 0.7 | C29: 0.7999 | D29: 2
C30: 0.6999 | D30: 0
B32: FASCE LDS — Scostamento medio vs SLA (↑ più alto = meglio)
B33: Scostamento (Da) | C33: Scostamento (A) | D33: Punteggio
B34: > 12% | D34: 10
B35: 0.081 | C35: 0.12 | D35: 8
B36: 0.051 | C36: 0.08 | D36: 6
B37: 0.031 | C37: 0.05 | D37: 4
B38: 0.011 | C38: 0.03 | D38: 2
B39: ≤ 1% | C39: 0.01 | D39: 0
B41: FASCE TMG — Scostamento % vs target (↓ meglio)
B42: Scostamento % (Da) | C42: Scostamento % (A) | D42: Punteggio
B43: ≤ -10% | C43: -0.1 | D43: 10
B44: -0.099 | C44: -0.05 | D44: 8
B45: -0.049 | C45: -0.001 | D45: 6
B46: 0 | C46: 0.049 | D46: 4
...

Sheet Dati Comparti
C1: Mese | D1: ='[1]db iniziale'!$B$1 -> 46296
C2: Dati al | D2: ='[1]Riepilogo mese per Commessa'!$D$1 -> 46321
B3: COMPARTO | C3: Produttività Target | D3: Produttività Reale | E3: Produttività Scost % | F3: IUQ % SLA in target | G3: LDS Scost. medio % | H3: TMG Target (secondi) | I3: TMG Reale (secondi) | J3: TMG Scost %
B4: Centro Servizi | C4: =INDEX([1]dati_comparti!D:D,MATCH($B4,[1]dati_comparti!$B:$B,0)) -> 0.64992908 | D4: =INDEX([1]dati_comparti!E:E,MATCH($B4,[1]dati_comparti!$B:$B,0)) -> 0.63987653 | E4: =IF(C4=0,"",IF(D4="","",(D4-C4))) -> -0.010052542 | F4: =INDEX([1]dati_comparti!G:G,MATCH($B4,[1]dati_comparti!$B:$B,0)) -> 0.61290323 | G4: =INDEX([1]dati_comparti!H:H,MATCH($B4,[1]dati_comparti!$B:$B,0)) -> 0.019894566 | H4: =INDEX([1]dati_comparti!I:I,MATCH($B4,[1]dati_comparti!$B:$B,0)) -> 232.07216 | I4: =INDEX([1]dati_comparti!J:J,MATCH($B4,[1]dati_comparti!$B:$B,0)) -> 238.5583 | J4: =IF(H4=0,"",IF(I4="","",(I4-H4)/H4)) -> 0.027948767
B5: Editoria | C5: =INDEX([1]dati_comparti!D:D,MATCH($B5,[1]dati_comparti!$B:$B,0)) -> 0.76087749 | D5: =INDEX([1]dati_comparti!E:E,MATCH($B5,[1]dati_comparti!$B:$B,0)) -> 0.82250446 | E5: =IF(C5=0,"",IF(D5="","",(D5-C5))) -> 0.061626973 | F5: =INDEX([1]dati_comparti!G:G,MATCH($B5,[1]dati_comparti!$B:$B,0)) -> 1 | G5: =INDEX([1]dati_comparti!H:H,MATCH($B5,[1]dati_comparti!$B:$B,0)) -> 0.036466513 | H5: =INDEX([1]dati_comparti!I:I,MATCH($B5,[1]dati_comparti!$B:$B,0)) -> 250.86809 | I5: =INDEX([1]dati_comparti!J:J,MATCH($B5,[1]dati_comparti!$B:$B,0)) -> 262.96749 | J5: =IF(H5=0,"",IF(I5="","",(I5-H5)/H5)) -> 0.048230124
B6: Gori | C6: =INDEX([1]dati_comparti!D:D,MATCH($B6,[1]dati_comparti!$B:$B,0)) -> 0.78878755 | D6: =INDEX([1]dati_comparti!E:E,MATCH($B6,[1]dati_comparti!$B:$B,0)) -> 0.83237517 | E6: =IF(C6=0,"",IF(D6="","",(D6-C6))) -> 0.043587628 | F6: =INDEX([1]dati_comparti!G:G,MATCH($B6,[1]dati_comparti!$B:$B,0)) -> 0.96457448 | G6: =INDEX([1]dati_comparti!H:H,MATCH($B6,[1]dati_comparti!$B:$B,0)) -> 0.0045744827 | H6: =INDEX([1]dati_comparti!I:I,MATCH($B6,[1]dati_comparti!$B:$B,0)) -> 218.70039 | I6: =INDEX([1]dati_comparti!J:J,MATCH($B6,[1]dati_comparti!$B:$B,0)) -> 230.70189 | J6: =IF(H6=0,"",IF(I6="","",(I6-H6)/H6)) -> 0.054876436
B7: Idrico | C7: =INDEX([1]dati_comparti!D:D,MATCH($B7,[1]dati_comparti!$B:$B,0)) -> 0.61747392 | D7: =INDEX([1]dati_comparti!E:E,MATCH($B7,[1]dati_comparti!$B:$B,0)) -> 0.56970182 | E7: =IF(C7=0,"",IF(D7="","",(D7-C7))) -> -0.047772104 | F7: =INDEX([1]dati_comparti!G:G,MATCH($B7,[1]dati_comparti!$B:$B,0)) -> 0.83928571 | G7: =INDEX([1]dati_comparti!H:H,MATCH($B7,[1]dati_comparti!$B:$B,0)) -> 0.040759356 | H7: =INDEX([1]dati_comparti!I:I,MATCH($B7,[1]dati_comparti!$B:$B,0)) -> 200.75789 | I7: =INDEX([1]dati_comparti!J:J,MATCH($B7,[1]dati_comparti!$B:$B,0)) -> 198.11585 | J7: =IF(H7=0,"",IF(I7="","",(I7-H7)/H7)) -> -0.013160343
B8: Igiene Ambientale | C8: =INDEX([1]dati_comparti!D:D,MATCH($B8,[1]dati_comparti!$B:$B,0)) -> 0.6327 | D8: =INDEX([1]dati_comparti!E:E,MATCH($B8,[1]dati_comparti!$B:$B,0)) -> 0.32377269 | E8: =IF(C8=0,"",IF(D8="","",(D8-C8))) -> -0.30892731 | F8: =INDEX([1]dati_comparti!G:G,MATCH($B8,[1]dati_comparti!$B:$B,0)) -> 0.94117647 | G8: =INDEX([1]dati_comparti!H:H,MATCH($B8,[1]dati_comparti!$B:$B,0)) -> 0.043574116 | H8: =INDEX([1]dati_comparti!I:I,MATCH($B8,[1]dati_comparti!$B:$B,0)) -> 146.5304 | I8: =INDEX([1]dati_comparti!J:J,MATCH($B8,[1]dati_comparti!$B:$B,0)) -> 202.23722 | J8: =IF(H8=0,"",IF(I8="","",(I8-H8)/H8)) -> 0.38017245
B9: ITS | C9: =INDEX([1]dati_comparti!D:D,MATCH($B9,[1]dati_comparti!$B:$B,0)) -> 0.67570554 | D9: =INDEX([1]dati_comparti!E:E,MATCH($B9,[1]dati_comparti!$B:$B,0)) -> 0.56454652 | E9: =IF(C9=0,"",IF(D9="","",(D9-C9))) -> -0.11115902 | F9: =INDEX([1]dati_comparti!G:G,MATCH($B9,[1]dati_comparti!$B:$B,0)) -> 0.75 | G9: =INDEX([1]dati_comparti!H:H,MATCH($B9,[1]dati_comparti!$B:$B,0)) -> 0.045052348 | H9: =INDEX([1]dati_comparti!I:I,MATCH($B9,[1]dati_comparti!$B:$B,0)) -> 149.81254 | I9: =INDEX([1]dati_comparti!J:J,MATCH($B9,[1]dati_comparti!$B:$B,0)) -> 168.92666 | J9: =IF(H9=0,"",IF(I9="","",(I9-H9)/H9)) -> 0.12758695
B10: Medicale | C10: =INDEX([1]dati_comparti!D:D,MATCH($B10,[1]dati_comparti!$B:$B,0)) -> 0.65018365 | D10: =INDEX([1]dati_comparti!E:E,MATCH($B10,[1]dati_comparti!$B:$B,0)) -> 0.67060738 | E10: =IF(C10=0,"",IF(D10="","",(D10-C10))) -> 0.02042373 | F10: =INDEX([1]dati_comparti!G:G,MATCH($B10,[1]dati_comparti!$B:$B,0)) -> 0.68421053 | G10: =INDEX([1]dati_comparti!H:H,MATCH($B10,[1]dati_comparti!$B:$B,0)) -> 0.019596617 | H10: =INDEX([1]dati_comparti!I:I,MATCH($B10,[1]dati_comparti!$B:$B,0)) -> 184.92501 | I10: =INDEX([1]dati_comparti!J:J,MATCH($B10,[1]dati_comparti!$B:$B,0)) -> 189.30635 | J10: =IF(H10=0,"",IF(I10="","",(I10-H10)/H10)) -> 0.023692469

Sheet Scoring
B2: 🏆 SCORING COMPARTI
B4: COMPARTO | C4: Punteggio Produttività | D4: Punteggio IUQ | E4: Punteggio LDS | F4: Punteggio TMG | G4: SCORE COMPOSITO
B5: ='Dati Comparti'!B4 -> Centro Servizi | C5: =IF('Dati Comparti'!E4="","",IF('Dati Comparti'!E4>=0.08,Parametri!$D$14,IF('Dati Comparti'!E4>=Parametri!$B$15,Parametri!$D$15,IF('Dati Comparti'!E4>=Parametri!$B$16,Parametri!$D$16,IF('Dati Comparti'!E4>=Parametri!$B$17,Parametri!$D$17,IF('Dati Comparti'!E4>=Parametri!$B$18,Parametri!$D$18,IF('Dati Comparti'!E4>=Parametri!$B$19,Parametri!$D$19,IF('Dati Comparti'!E4>Parametri!$C$21,Parametri!$D$20,Parametri!$D$21)))))))) -> -2 | D5: =IF('Dati Comparti'!F4="","",IF('Dati Comparti'!F4>=0.95,Parametri!$D$25,IF('Dati Comparti'!F4>=Parametri!$B$26,Parametri!$D$26,IF('Dati Comparti'!F4>=Parametri!$B$27,Parametri!$D$27,IF('Dati Comparti'!F4>=Parametri!$B$28,Parametri!$D$28,IF('Dati Comparti'!F4>=Parametri!$B$29,Parametri!$D$29,Parametri!$D$30)))))) -> 0 | E5: =IF('Dati Comparti'!G4="","",IF('Dati Comparti'!G4>0.12,Parametri!$D$34,IF('Dati Comparti'!G4>=Parametri!$B$35,Parametri!$D$35,IF('Dati Comparti'!G4>=Parametri!$B$36,Parametri!$D$36,IF('Dati Comparti'!G4>=Parametri!$B$37,Parametri!$D$37,IF('Dati Comparti'!G4>=Parametri!$B$38,Parametri!$D$38,Parametri!$D$39)))))) -> 2 | F5: =IF('Dati Comparti'!J4="","",IF('Dati Comparti'!J4<=Parametri!$C$43,Parametri!$D$43,IF('Dati Comparti'!J4<=Parametri!$C$44,Parametri!$D$44,IF('Dati Comparti'!J4<=Parametri!$C$45,Parametri!$D$45,IF('Dati Comparti'!J4<=Parametri!$C$46,Parametri!$D$46,IF('Dati Comparti'!J4<=Parametri!$C$47,Parametri!$D$47,Parametri!$D$48)))))) -> 4 | G5: =IF(OR(C5="",D5="",E5="",F5=""),"",ROUND(C5*Parametri!C6+D5*Parametri!C7+E5*Parametri!C8+F5*Parametri!C9,2)) -> 0
B6: ='Dati Comparti'!B5 -> Editoria | C6: =IF('Dati Comparti'!E5="","",IF('Dati Comparti'!E5>=0.08,Parametri!$D$14,IF('Dati Comparti'!E5>=Parametri!$B$15,Parametri!$D$15,IF('Dati Comparti'!E5>=Parametri!$B$16,Parametri!$D$16,IF('Dati Comparti'!E5>=Parametri!$B$17,Parametri!$D$17,IF('Dati Comparti'!E5>=Parametri!$B$18,Parametri!$D$18,IF('Dati Comparti'!E5>=Parametri!$B$19,Parametri!$D$19,IF('Dati Comparti'!E5>Parametri!$C$21,Parametri!$D$20,Parametri!$D$21)))))))) -> 8 | D6: =IF('Dati Comparti'!F5="","",IF('Dati Comparti'!F5>=0.95,Parametri!$D$25,IF('Dati Comparti'!F5>=Parametri!$B$26,Parametri!$D$26,IF('Dati Comparti'!F5>=Parametri!$B$27,Parametri!$D$27,IF('Dati Comparti'!F5>=Parametri!$B$28,Parametri!$D$28,IF('Dati Comparti'!F5>=Parametri!$B$29,Parametri!$D$29,Parametri!$D$30)))))) -> 10 | E6: =IF('Dati Comparti'!G5="","",IF('Dati Comparti'!G5>0.12,Parametri!$D$34,IF('Dati Comparti'!G5>=Parametri!$B$35,Parametri!$D$35,IF('Dati Comparti'!G5>=Parametri!$B$36,Parametri!$D$36,IF('Dati Comparti'!G5>=Parametri!$B$37,Parametri!$D$37,IF('Dati Comparti'!G5>=Parametri!$B$38,Parametri!$D$38,Parametri!$D$39)))))) -> 4 | F6: =IF('Dati Comparti'!J5="","",IF('Dati Comparti'!J5<=Parametri!$C$43,Parametri!$D$43,IF('Dati Comparti'!J5<=Parametri!$C$44,Parametri!$D$44,IF('Dati Comparti'!J5<=Parametri!$C$45,Parametri!$D$45,IF('Dati Comparti'!J5<=Parametri!$C$46,Parametri!$D$46,IF('Dati Comparti'!J5<=Parametri!$C$47,Parametri!$D$47,Parametri!$D$48)))))) -> 4 | G6: =IF(OR(C6="",D6="",E6="",F6=""),"",ROUND(C6*Parametri!C6+D6*Parametri!C7+E6*Parametri!C8+F6*Parametri!C9,2)) -> 7.4
B7: ='Dati Comparti'!B6 -> Gori | C7: =IF('Dati Comparti'!E6="","",IF('Dati Comparti'!E6>=0.08,Parametri!$D$14,IF('Dati Comparti'!E6>=Parametri!$B$15,Parametri!$D$15,IF('Dati Comparti'!E6>=Parametri!$B$16,Parametri!$D$16,IF('Dati Comparti'!E6>=Parametri!$B$17,Parametri!$D$17,IF('Dati Comparti'!E6>=Parametri!$B$18,Parametri!$D$18,IF('Dati Comparti'!E6>=Parametri!$B$19,Parametri!$D$19,IF('Dati Comparti'!E6>Parametri!$C$21,Parametri!$D$20,Parametri!$D$21)))))))) -> 6 | D7: =IF('Dati Comparti'!F6="","",IF('Dati Comparti'!F6>=0.95,Parametri!$D$25,IF('Dati Comparti'!F6>=Parametri!$B$26,Parametri!$D$26,IF('Dati Comparti'!F6>=Parametri!$B$27,Parametri!$D$27,IF('Dati Comparti'!F6>=Parametri!$B$28,Parametri!$D$28,IF('Dati Comparti'!F6>=Parametri!$B$29,Parametri!$D$29,Parametri!$D$30)))))) -> 10 | E7: =IF('Dati Comparti'!G6="","",IF('Dati Comparti'!G6>0.12,Parametri!$D$34,IF('Dati Comparti'!G6>=Parametri!$B$35,Parametri!$D$35,IF('Dati Comparti'!G6>=Parametri!$B$36,Parametri!$D$36,IF('Dati Comparti'!G6>=Parametri!$B$37,Parametri!$D$37,IF('Dati Comparti'!G6>=Parametri!$B$38,Parametri!$D$38,Parametri!$D$39)))))) -> 0 | F7: =IF('Dati Comparti'!J6="","",IF('Dati Comparti'!J6<=Parametri!$C$43,Parametri!$D$43,IF('Dati Comparti'!J6<=Parametri!$C$44,Parametri!$D$44,IF('Dati Comparti'!J6<=Parametri!$C$45,Parametri!$D$45,IF('Dati Comparti'!J6<=Parametri!$C$46,Parametri!$D$46,IF('Dati Comparti'!J6<=Parametri!$C$47,Parametri!$D$47,Parametri!$D$48)))))) -> 2 | G7: =IF(OR(C7="",D7="",E7="",F7=""),"",ROUND(C7*Parametri!C6+D7*Parametri!C7+E7*Parametri!C8+F7*Parametri!C9,2)) -> 5.6
B8: ='Dati Comparti'!B7 -> Idrico | C8: =IF('Dati Comparti'!E7="","",IF('Dati Comparti'!E7>=0.08,Parametri!$D$14,IF('Dati Comparti'!E7>=Parametri!$B$15,Parametri!$D$15,IF('Dati Comparti'!E7>=Parametri!$B$16,Parametri!$D$16,IF('Dati Comparti'!E7>=Parametri!$B$17,Parametri!$D$17,IF('Dati Comparti'!E7>=Parametri!$B$18,Parametri!$D$18,IF('Dati Comparti'!E7>=Parametri!$B$19,Parametri!$D$19,IF('Dati Comparti'!E7>Parametri!$C$21,Parametri!$D$20,Parametri!$D$21)))))))) -> -10 | D8: =IF('Dati Comparti'!F7="","",IF('Dati Comparti'!F7>=0.95,Parametri!$D$25,IF('Dati Comparti'!F7>=Parametri!$B$26,Parametri!$D$26,IF('Dati Comparti'!F7>=Parametri!$B$27,Parametri!$D$27,IF('Dati Comparti'!F7>=Parametri!$B$28,Parametri!$D$28,IF('Dati Comparti'!F7>=Parametri!$B$29,Parametri!$D$29,Parametri!$D$30)))))) -> 4 | E8: =IF('Dati Comparti'!G7="","",IF('Dati Comparti'!G7>0.12,Parametri!$D$34,IF('Dati Comparti'!G7>=Parametri!$B$35,Parametri!$D$35,IF('Dati Comparti'!G7>=Parametri!$B$36,Parametri!$D$36,IF('Dati Comparti'!G7>=Parametri!$B$37,Parametri!$D$37,IF('Dati Comparti'!G7>=Parametri!$B$38,Parametri!$D$38,Parametri!$D$39)))))) -> 4 | F8: =IF('Dati Comparti'!J7="","",IF('Dati Comparti'!J7<=Parametri!$C$43,Parametri!$D$43,IF('Dati Comparti'!J7<=Parametri!$C$44,Parametri!$D$44,IF('Dati Comparti'!J7<=Parametri!$C$45,Parametri!$D$45,IF('Dati Comparti'!J7<=Parametri!$C$46,Parametri!$D$46,IF('Dati Comparti'!J7<=Parametri!$C$47,Parametri!$D$47,Parametri!$D$48)))))) -> 6 | G8: =IF(OR(C8="",D8="",E8="",F8=""),"",ROUND(C8*Parametri!C6+D8*Parametri!C7+E8*Parametri!C8+F8*Parametri!C9,2)) -> -1.4
B9: ='Dati Comparti'!B8 -> Igiene Ambientale | C9: =IF('Dati Comparti'!E8="","",IF('Dati Comparti'!E8>=0.08,Parametri!$D$14,IF('Dati Comparti'!E8>=Parametri!$B$15,Parametri!$D$15,IF('Dati Comparti'!E8>=Parametri!$B$16,Parametri!$D$16,IF('Dati Comparti'!E8>=Parametri!$B$17,Parametri!$D$17,IF('Dati Comparti'!E8>=Parametri!$B$18,Parametri!$D$18,IF('Dati Comparti'!E8>=Parametri!$B$19,Parametri!$D$19,IF('Dati Comparti'!E8>Parametri!$C$21,Parametri!$D$20,Parametri!$D$21)))))))) -> -10 | D9: =IF('Dati Comparti'!F8="","",IF('Dati Comparti'!F8>=0.95,Parametri!$D$25,IF('Dati Comparti'!F8>=Parametri!$B$26,Parametri!$D$26,IF('Dati Comparti'!F8>=Parametri!$B$27,Parametri!$D$27,IF('Dati Comparti'!F8>=Parametri!$B$28,Parametri!$D$28,IF('Dati Comparti'!F8>=Parametri!$B$29,Parametri!$D$29,Parametri!$D$30)))))) -> 8 | E9: =IF('Dati Comparti'!G8="","",IF('Dati Comparti'!G8>0.12,Parametri!$D$34,IF('Dati Comparti'!G8>=Parametri!$B$35,Parametri!$D$35,IF('Dati Comparti'!G8>=Parametri!$B$36,Parametri!$D$36,IF('Dati Comparti'!G8>=Parametri!$B$37,Parametri!$D$37,IF('Dati Comparti'!G8>=Parametri!$B$38,Parametri!$D$38,Parametri!$D$39)))))) -> 4 | F9: =IF('Dati Comparti'!J8="","",IF('Dati Comparti'!J8<=Parametri!$C$43,Parametri!$D$43,IF('Dati Comparti'!J8<=Parametri!$C$44,Parametri!$D$44,IF('Dati Comparti'!J8<=Parametri!$C$45,Parametri!$D$45,IF('Dati Comparti'!J8<=Parametri!$C$46,Parametri!$D$46,IF('Dati Comparti'!J8<=Parametri!$C$47,Parametri!$D$47,Parametri!$D$48)))))) -> 0 | G9: =IF(OR(C9="",D9="",E9="",F9=""),"",ROUND(C9*Parametri!C6+D9*Parametri!C7+E9*Parametri!C8+F9*Parametri!C9,2)) -> -0.8
B10: ITS | C10: =IF('Dati Comparti'!E9="","",IF('Dati Comparti'!E9>=0.08,Parametri!$D$14,IF('Dati Comparti'!E9>=Parametri!$B$15,Parametri!$D$15,IF('Dati Comparti'!E9>=Parametri!$B$16,Parametri!$D$16,IF('Dati Comparti'!E9>=Parametri!$B$17,Parametri!$D$17,IF('Dati Comparti'!E9>=Parametri!$B$18,Parametri!$D$18,IF('Dati Comparti'!E9>=Parametri!$B$19,Parametri!$D$19,IF('Dati Comparti'!E9>Parametri!$C$21,Parametri!$D$20,Parametri!$D$21)))))))) -> -10 | D10: =IF('Dati Comparti'!F9="","",IF('Dati Comparti'!F9>=0.95,Parametri!$D$25,IF('Dati Comparti'!F9>=Parametri!$B$26,Parametri!$D$26,IF('Dati Comparti'!F9>=Parametri!$B$27,Parametri!$D$27,IF('Dati Comparti'!F9>=Parametri!$B$28,Parametri!$D$28,IF('Dati Comparti'!F9>=Parametri!$B$29,Parametri!$D$29,Parametri!$D$30)))))) -> 2 | E10: =IF('Dati Comparti'!G9="","",IF('Dati Comparti'!G9>0.12,Parametri!$D$34,IF('Dati Comparti'!G9>=Parametri!$B$35,Parametri!$D$35,IF('Dati Comparti'!G9>=Parametri!$B$36,Parametri!$D$36,IF('Dati Comparti'!G9>=Parametri!$B$37,Parametri!$D$37,IF('Dati Comparti'!G9>=Parametri!$B$38,Parametri!$D$38,Parametri!$D$39)))))) -> 4 | F10: =IF('Dati Comparti'!J9="","",IF('Dati Comparti'!J9<=Parametri!$C$43,Parametri!$D$43,IF('Dati Comparti'!J9<=Parametri!$C$44,Parametri!$D$44,IF('Dati Comparti'!J9<=Parametri!$C$45,Parametri!$D$45,IF('Dati Comparti'!J9<=Parametri!$C$46,Parametri!$D$46,IF('Dati Comparti'!J9<=Parametri!$C$47,Parametri!$D$47,Parametri!$D$48)))))) -> 0 | G10: =IF(OR(C10="",D10="",E10="",F10=""),"",ROUND(C10*Parametri!C6+D10*Parametri!C7+E10*Parametri!C8+F10*Parametri!C9,2)) -> -2.6
B11: Medicale | C11: =IF('Dati Comparti'!E10="","",IF('Dati Comparti'!E10>=0.08,Parametri!$D$14,IF('Dati Comparti'!E10>=Parametri!$B$15,Parametri!$D$15,IF('Dati Comparti'!E10>=Parametri!$B$16,Parametri!$D$16,IF('Dati Comparti'!E10>=Parametri!$B$17,Parametri!$D$17,IF('Dati Comparti'!E10>=Parametri!$B$18,Parametri!$D$18,IF('Dati Comparti'!E10>=Parametri!$B$19,Parametri!$D$19,IF('Dati Comparti'!E10>Parametri!$C$21,Parametri!$D$20,Parametri!$D$21)))))))) -> 4 | D11: =IF('Dati Comparti'!F10="","",IF('Dati Comparti'!F10>=0.95,Parametri!$D$25,IF('Dati Comparti'!F10>=Parametri!$B$26,Parametri!$D$26,IF('Dati Comparti'!F10>=Parametri!$B$27,Parametri!$D$27,IF('Dati Comparti'!F10>=Parametri!$B$28,Parametri!$D$28,IF('Dati Comparti'!F10>=Parametri!$B$29,Parametri!$D$29,Parametri!$D$30)))))) -> 0 | E11: =IF('Dati Comparti'!G10="","",IF('Dati Comparti'!G10>0.12,Parametri!$D$34,IF('Dati Comparti'!G10>=Parametri!$B$35,Parametri!$D$35,IF('Dati Comparti'!G10>=Parametri!$B$36,Parametri!$D$36,IF('Dati Comparti'!G10>=Parametri!$B$37,Parametri!$D$37,IF('Dati Comparti'!G10>=Parametri!$B$38,Parametri!$D$38,Parametri!$D$39)))))) -> 2 | F11: =IF('Dati Comparti'!J10="","",IF('Dati Comparti'!J10<=Parametri!$C$43,Parametri!$D$43,IF('Dati Comparti'!J10<=Parametri!$C$44,Parametri!$D$44,IF('Dati Comparti'!J10<=Parametri!$C$45,Parametri!$D$45,IF('Dati Comparti'!J10<=Parametri!$C$46,Parametri!$D$46,IF('Dati Comparti'!J10<=Parametri!$C$47,Parametri!$D$47,Parametri!$D$48)))))) -> 4 | G11: =IF(OR(C11="",D11="",E11="",F11=""),"",ROUND(C11*Parametri!C6+D11*Parametri!C7+E11*Parametri!C8+F11*Parametri!C9,2)) -> 2.4
B13: 🥇 CLASSIFICA FINALE
B14: Posizione | C14: Comparto | G14: Score Composito
B15: 🥇 | C15: =IFERROR(INDEX(Scoring!B5:B11,MATCH(LARGE(Scoring!G5:G11,1),Scoring!G5:G11,0)),"") -> Editoria | G15: =IFERROR(LARGE(Scoring!G5:G11,1),"") -> 7.4
B16: 🥈 | C16: =IFERROR(INDEX(Scoring!B5:B11,MATCH(LARGE(Scoring!G5:G11,2),Scoring!G5:G11,0)),"") -> Gori | G16: =IFERROR(LARGE(Scoring!G5:G11,2),"") -> 5.6
B17: 🥉 | C17: =IFERROR(INDEX(Scoring!B5:B11,MATCH(LARGE(Scoring!G5:G11,3),Scoring!G5:G11,0)),"") -> Medicale | G17: =IFERROR(LARGE(Scoring!G5:G11,3),"") -> 2.4
B18: 4° | C18: =IFERROR(INDEX(Scoring!B5:B11,MATCH(LARGE(Scoring!G5:G11,4),Scoring!G5:G11,0)),"") -> Centro Servizi | G18: =IFERROR(LARGE(Scoring!G5:G11,4),"") -> 0
B19: 5° | C19: =IFERROR(INDEX(Scoring!B5:B11,MATCH(LARGE(Scoring!G5:G11,5),Scoring!G5:G11,0)),"") -> Igiene Ambientale | G19: =IFERROR(LARGE(Scoring!G5:G11,5),"") -> -0.8
B20: 6° | C20: =IFERROR(INDEX(Scoring!B5:B11,MATCH(LARGE(Scoring!G5:G11,6),Scoring!G5:G11,0)),"") -> Idrico | G20: =IFERROR(LARGE(Scoring!G5:G11,6),"") -> -1.4
B21: 7° | C21: =IFERROR(INDEX(Scoring!B5:B11,MATCH(LARGE(Scoring!G5:G11,7),Scoring!G5:G11,0)),"") -> ITS | G21: =IFERROR(LARGE(Scoring!G5:G11,7),"") -> -2.6
B23: Formula: Score = Prod×40% + IUQ×30% + LDS×20% + TMG×10% | Pesi e fasce modificabili nel foglio Parametri

Sheet Storico
A1: Mese | B1: Comparto | C1: Produttività | D1: IUQ | E1: LDS | F1: TMG | G1: Score
A2: 2026-06 | B2: Centro Servizi | C2: 10 | D2: 2 | E2: 2 | F2: 6 | G2: 5.6
A3: 2026-06 | B3: Editoria | C3: -5 | D3: 10 | E3: 4 | F3: 4 | G3: 2.2
A4: 2026-06 | B4: Gori | C4: -10 | D4: 10 | E4: 2 | F4: 4 | G4: -0.2
A5: 2026-06 | B5: Idrico | C5: 6 | D5: 0 | E5: 0 | F5: 6 | G5: 3
A6: 2026-06 | B6: Igiene Ambientale | C6: -10 | D6: 0 | E6: 0 | F6: 8 | G6: -3.2
A7: 2026-06 | B7: ITS | C7: -10 | D7: 0 | E7: 0 | F7: 10 | G7: -3
A8: 2026-06 | B8: Medicale | C8: 6 | D8: 0 | E8: 0 | F8: 4 | G8: 2.8
A9: 2026-07 | B9: Centro Servizi | C9: 10 | D9: 0 | E9: 0 | F9: 6 | G9: 4.6
A10: 2026-07 | B10: Editoria | C10: 10 | D10: 10 | E10: 4 | F10: 0 | G10: 7.8
A11: 2026-07 | B11: Gori | C11: -10 | D11: 10 | E11: 2 | F11: 4 | G11: -0.2
A12: 2026-07 | B12: Idrico | C12: 4 | D12: 0 | E12: 0 | F12: 4 | G12: 2
A13: 2026-07 | B13: Igiene Ambientale | C13: -10 | D13: 0 | E13: 0 | F13: 0 | G13: -4
... A36: 2026-10 | B36: Medicale | C36: 4 | D36: 0 | E36: 2 | F36: 4 | G36: 2.4
